2025-03-22 18:21:06,946 - INFO - \U0001f680 Starting Git commit and notification process...
2025-03-22 18:21:07,044 - ERROR - \u274c Error running auto_git_commit.py: Traceback (most recent call last):
  File "C:\Users\samqu\OneDrive - Digital Age Marketing Group\Desktop\Local Py\Work Projects\bar-directory-recon\auto_git_commit.py", line 44, in <module>
    git_commit_and_push()
    ~~~~~~~~~~~~~~~~~~~^^
  File "C:\Users\samqu\OneDrive - Digital Age Marketing Group\Desktop\Local Py\Work Projects\bar-directory-recon\auto_git_commit.py", line 19, in git_commit_and_push
    status_output = subprocess.run(["git", "status", "--porcelain"], capture_output=True, text=True)
  File "C:\Program Files\Python313\Lib\subprocess.py", line 556, in run
    with Popen(*popenargs, **kwargs) as process:
         ~~~~~^^^^^^^^^^^^^^^^^^^^^^
  File "C:\Program Files\Python313\Lib\subprocess.py", line 1038, in __init__
    self._execute_child(args, executable, preexec_fn, close_fds,
    ~~~~~~~~~~~~~~~~~~~^^^^^^^^^^^^^^^^^^^^^^^^^^^^^^^^^^^^^^^^^
                        pass_fds, cwd, env,
                        ^^^^^^^^^^^^^^^^^^^
    ...<5 lines>...
                        gid, gids, uid, umask,
                        ^^^^^^^^^^^^^^^^^^^^^^
                        start_new_session, process_group)
                        ^^^^^^^^^^^^^^^^^^^^^^^^^^^^^^^^^
  File "C:\Program Files\Python313\Lib\subprocess.py", line 1550, in _execute_child
    hp, ht, pid, tid = _winapi.CreateProcess(executable, args,
                       ~~~~~~~~~~~~~~~~~~~~~^^^^^^^^^^^^^^^^^^
                             # no special security
                             ^^^^^^^^^^^^^^^^^^^^^
    ...<4 lines>...
                             cwd,
                             ^^^^
                             startupinfo)
                             ^^^^^^^^^^^^
FileNotFoundError: [WinError 2] The system cannot find the file specified

2025-03-22 18:21:08,624 - ERROR - \u274c Error running asus_notifier.py: Traceback (most recent call last):
  File "C:\Users\samqu\OneDrive - Digital Age Marketing Group\Desktop\Local Py\Work Projects\bar-directory-recon\asus_notifier.py", line 64, in send_email
    print("\u2705 HTML Email sent successfully.")
    ~~~~~^^^^^^^^^^^^^^^^^^^^^^^^^^^^^^^^^^^^
  File "C:\Program Files\Python313\Lib\encodings\cp1252.py", line 19, in encode
    return codecs.charmap_encode(input,self.errors,encoding_table)[0]
           ~~~~~~~~~~~~~~~~~~~~~^^^^^^^^^^^^^^^^^^^^^^^^^^^^^^^^^^
UnicodeEncodeError: 'charmap' codec can't encode character '\u2705' in position 0: character maps to <undefined>

During handling of the above exception, another exception occurred:

Traceback (most recent call last):
  File "C:\Users\samqu\OneDrive - Digital Age Marketing Group\Desktop\Local Py\Work Projects\bar-directory-recon\asus_notifier.py", line 79, in <module>
    send_email("\U0001f680 Test HTML Notification from ASUS", html_content)
    ~~~~~~~~~~^^^^^^^^^^^^^^^^^^^^^^^^^^^^^^^^^^^^^^^^^^^^^^^^^^^^^
  File "C:\Users\samqu\OneDrive - Digital Age Marketing Group\Desktop\Local Py\Work Projects\bar-directory-recon\asus_notifier.py", line 71, in send_email
    print(f"\u274c Unexpected error: {e}")
    ~~~~~^^^^^^^^^^^^^^^^^^^^^^^^^^^^^
  File "C:\Program Files\Python313\Lib\encodings\cp1252.py", line 19, in encode
    return codecs.charmap_encode(input,self.errors,encoding_table)[0]
           ~~~~~~~~~~~~~~~~~~~~~^^^^^^^^^^^^^^^^^^^^^^^^^^^^^^^^^^
UnicodeEncodeError: 'charmap' codec can't encode character '\u274c' in position 0: character maps to <undefined>

2025-03-22 18:21:08,625 - INFO - \u2705 Process complete.
