
=================================== ERRORS ====================================
________________ ERROR collecting test_hallandale_pipeline.py _________________
import file mismatch:
imported module 'test_hallandale_pipeline' has this __file__ attribute:
  C:\Code\bar-directory-recon\src\tests\test_hallandale_pipeline.py
which is not the same as the test file we want to collect:
  C:\Code\bar-directory-recon\test_hallandale_pipeline.py
HINT: remove __pycache__ / .pyc files and/or use a unique basename for your test file modules
___________________ ERROR collecting test_live_scraping.py ____________________
ImportError while importing test module 'C:\Code\bar-directory-recon\test_live_scraping.py'.
Hint: make sure your test modules/packages have valid Python names.
Traceback:
C:\ProgramData\miniconda3\Lib\importlib\__init__.py:88: in import_module
    return _bootstrap._gcd_import(name[level:], package, level)
           ^^^^^^^^^^^^^^^^^^^^^^^^^^^^^^^^^^^^^^^^^^^^^^^^^^^^
test_live_scraping.py:15: in <module>
    from tools.realtor_directory_scraper import scrape_realtor_directory  # noqa: E402
    ^^^^^^^^^^^^^^^^^^^^^^^^^^^^^^^^^^^^^^^^^^^^^^^^^^^^^^^^^^^^^^^^^^^^
E   ImportError: cannot import name 'scrape_realtor_directory' from 'tools.realtor_directory_scraper' (C:\Code\bar-directory-recon\tools\realtor_directory_scraper.py)
_______________ ERROR collecting tests/test_security_manager.py _______________
import file mismatch:
imported module 'test_security_manager' has this __file__ attribute:
  C:\Code\bar-directory-recon\src\tests\test_security_manager.py
which is not the same as the test file we want to collect:
  C:\Code\bar-directory-recon\tests\test_security_manager.py
HINT: remove __pycache__ / .pyc files and/or use a unique basename for your test file modules
============================== warnings summary ===============================
universal_recon\tests\analytics\test_plugin_usage_diff.py:14
  C:\Code\bar-directory-recon\universal_recon\tests\analytics\test_plugin_usage_diff.py:14: PytestUnknownMarkWarning: Unknown pytest.mark.analytics - is this a typo?  You can register custom marks to avoid this warning - for details, see https://docs.pytest.org/en/stable/how-to/mark.html
    @pytest.mark.analytics

universal_recon\tests\analytics\test_risk_overlay_emitter.py:18
  C:\Code\bar-directory-recon\universal_recon\tests\analytics\test_risk_overlay_emitter.py:18: PytestUnknownMarkWarning: Unknown pytest.mark.analytics - is this a typo?  You can register custom marks to avoid this warning - for details, see https://docs.pytest.org/en/stable/how-to/mark.html
    @pytest.mark.analytics

.venv-ci\Lib\site-packages\_pytest\cacheprovider.py:475
  C:\Code\bar-directory-recon\.venv-ci\Lib\site-packages\_pytest\cacheprovider.py:475: PytestCacheWarning: could not create cache path C:\Code\bar-directory-recon\.pytest_cache\v\cache\nodeids: [WinError 5] Access is denied: 'C:\\Code\\bar-directory-recon\\.pytest_cache\\v\\cache'
    config.cache.set("cache/nodeids", sorted(self.cached_nodeids))

.venv-ci\Lib\site-packages\_pytest\cacheprovider.py:429
  C:\Code\bar-directory-recon\.venv-ci\Lib\site-packages\_pytest\cacheprovider.py:429: PytestCacheWarning: could not create cache path C:\Code\bar-directory-recon\.pytest_cache\v\cache\lastfailed: [WinError 5] Access is denied: 'C:\\Code\\bar-directory-recon\\.pytest_cache\\v\\cache'
    config.cache.set("cache/lastfailed", self.lastfailed)

-- Docs: https://docs.pytest.org/en/stable/how-to/capture-warnings.html
- generated xml file: C:\Code\bar-directory-recon\logs\nightly\junit_final.xml -
=========================== short test summary info ===========================
ERROR test_hallandale_pipeline.py
ERROR test_live_scraping.py
ERROR tests/test_security_manager.py
!!!!!!!!!!!!!!!!!!! Interrupted: 3 errors during collection !!!!!!!!!!!!!!!!!!!
5 deselected, 4 warnings, 3 errors in 2.15s
